{
 "cells": [
  {
   "cell_type": "code",
   "execution_count": 8,
   "metadata": {},
   "outputs": [],
   "source": [
    "import numpy as np\n",
    "import pandas as pd\n",
    "\n",
    "pheno_train = pd.read_csv(\"train/pheno_training.csv\")\n",
    "readcounts_train = pd.read_csv(\"train/readcounts_training.csv\")\n",
    "taxtable_train = pd.read_csv(\"train/taxtable.csv\")\n",
    "\n",
    "pheno_test = pd.read_csv(\"test/pheno_test.csv\")\n",
    "readcounts_test = pd.read_csv(\"test/readcounts_test.csv\")\n",
    "taxtable_test = pd.read_csv(\"test/taxtable.csv\")\n",
    "\n",
    "pheno_train = pheno_train.dropna()\n",
    "pheno_test = pheno_test.dropna()"
   ]
  },
  {
   "cell_type": "markdown",
   "metadata": {},
   "source": [
    "#### Pré processamento para ML"
   ]
  },
  {
   "cell_type": "code",
   "execution_count": 9,
   "metadata": {},
   "outputs": [],
   "source": [
    "pheno_train_y = pheno_train.PrevalentHFAIL\n",
    "pheno_train_X = pheno_train.iloc[: , 1:]\n",
    "pheno_train_X = pheno_train_X.loc[:, pheno_train_X.columns != \"PrevalentHFAIL\"]\n",
    "pheno_test_y = pheno_test.PrevalentHFAIL\n",
    "pheno_test_X = pheno_test.iloc[: , 1:]\n",
    "pheno_test_X = pheno_test_X.loc[:, pheno_test_X.columns != \"PrevalentHFAIL\"]\n"
   ]
  },
  {
   "cell_type": "markdown",
   "metadata": {},
   "source": [
    "#### Logistic Regression"
   ]
  },
  {
   "cell_type": "code",
   "execution_count": 10,
   "metadata": {},
   "outputs": [
    {
     "name": "stdout",
     "output_type": "stream",
     "text": [
      "PECC (accuracy): 1.0\n"
     ]
    }
   ],
   "source": [
    "from sklearn import linear_model\n",
    "from sklearn.metrics import accuracy_score\n",
    "\n",
    "logistic = linear_model.LogisticRegression(C=1e5, solver = \"liblinear\", multi_class = \"auto\")\n",
    "logistic = logistic.fit(pheno_train_X, pheno_train_y)\n",
    "logistic_prev = logistic.predict(pheno_test_X)\n",
    "\n",
    "print(\"PECC (accuracy):\", accuracy_score(pheno_test_y, logistic_prev))"
   ]
  },
  {
   "cell_type": "markdown",
   "metadata": {},
   "source": [
    "#### Linear Regression"
   ]
  },
  {
   "cell_type": "code",
   "execution_count": 11,
   "metadata": {},
   "outputs": [
    {
     "name": "stdout",
     "output_type": "stream",
     "text": [
      "[-0.05287802  0.08292254 -0.03657902 ...  0.24002286  0.00915692\n",
      " -0.03806369]\n",
      "Não funciona com boleans\n"
     ]
    }
   ],
   "source": [
    "from sklearn import linear_model\n",
    "from sklearn.model_selection import cross_val_score\n",
    "\n",
    "regr_model = linear_model.LinearRegression()\n",
    "regr_model = regr_model.fit(pheno_train_X, pheno_train_y)\n",
    "regr_model_pred = regr_model.predict(pheno_test_X)\n",
    "\n",
    "print(regr_model_pred)\n",
    "\n",
    "#print(\"PECC (accuracy):\", accuracy_score(pheno_test_y, regr_model_pred))\n",
    "print(\"Não funciona com boleans\")"
   ]
  },
  {
   "cell_type": "markdown",
   "metadata": {},
   "source": [
    "#### Ridge\n"
   ]
  },
  {
   "cell_type": "code",
   "execution_count": 12,
   "metadata": {},
   "outputs": [
    {
     "name": "stdout",
     "output_type": "stream",
     "text": [
      "[-0.0528788   0.0829221  -0.03657104 ...  0.24002048  0.00915614\n",
      " -0.03806499]\n",
      "Não funciona com boleans\n"
     ]
    }
   ],
   "source": [
    "ridge = linear_model.Ridge(alpha=.1)\n",
    "ridge = ridge.fit(pheno_train_X, pheno_train_y)\n",
    "ridge_pred = ridge.predict(pheno_test_X)\n",
    "\n",
    "print(ridge_pred)\n",
    "#print(\"PECC (accuracy):\", accuracy_score(pheno_test_y, ridge_pred))\n",
    "print(\"Não funciona com boleans\")"
   ]
  },
  {
   "cell_type": "markdown",
   "metadata": {},
   "source": [
    "Lasso"
   ]
  },
  {
   "cell_type": "code",
   "execution_count": 13,
   "metadata": {},
   "outputs": [
    {
     "name": "stdout",
     "output_type": "stream",
     "text": [
      "[0.0259887 0.0259887 0.0259887 ... 0.0259887 0.0259887 0.0259887]\n",
      "Não funciona com boleans\n"
     ]
    }
   ],
   "source": [
    "lasso = linear_model.Lasso()\n",
    "lasso = lasso.fit(pheno_train_X, pheno_train_y)\n",
    "lasso_pred = lasso.predict(pheno_test_X)\n",
    "print(lasso_pred)\n",
    "#print(\"PECC (accuracy):\", accuracy_score(pheno_test_y, lasso_pred))\n",
    "print(\"Não funciona com boleans\")"
   ]
  },
  {
   "cell_type": "markdown",
   "metadata": {},
   "source": [
    "## SVM's"
   ]
  },
  {
   "cell_type": "code",
   "execution_count": 19,
   "metadata": {},
   "outputs": [
    {
     "name": "stdout",
     "output_type": "stream",
     "text": [
      "PECC (accuracy): 0.9965986394557823\n"
     ]
    },
    {
     "ename": "ValueError",
     "evalue": "\nAll the 5 fits failed.\nIt is very likely that your model is misconfigured.\nYou can try to debug the error by setting error_score='raise'.\n\nBelow are more details about the failures:\n--------------------------------------------------------------------------------\n1 fits failed with the following error:\nTraceback (most recent call last):\n  File \"/usr/local/lib/python3.10/dist-packages/sklearn/model_selection/_validation.py\", line 686, in _fit_and_score\n    estimator.fit(X_train, y_train, **fit_params)\n  File \"/usr/local/lib/python3.10/dist-packages/sklearn/svm/_base.py\", line 173, in fit\n    X, y = self._validate_data(\n  File \"/usr/local/lib/python3.10/dist-packages/sklearn/base.py\", line 596, in _validate_data\n    X, y = check_X_y(X, y, **check_params)\n  File \"/usr/local/lib/python3.10/dist-packages/sklearn/utils/validation.py\", line 1074, in check_X_y\n    X = check_array(\n  File \"/usr/local/lib/python3.10/dist-packages/sklearn/utils/validation.py\", line 879, in check_array\n    raise ValueError(\nValueError: Expected 2D array, got 1D array instead:\narray=[1. 1. 0. ... 0. 0. 0.].\nReshape your data either using array.reshape(-1, 1) if your data has a single feature or array.reshape(1, -1) if it contains a single sample.\n\n--------------------------------------------------------------------------------\n4 fits failed with the following error:\nTraceback (most recent call last):\n  File \"/usr/local/lib/python3.10/dist-packages/sklearn/model_selection/_validation.py\", line 686, in _fit_and_score\n    estimator.fit(X_train, y_train, **fit_params)\n  File \"/usr/local/lib/python3.10/dist-packages/sklearn/svm/_base.py\", line 173, in fit\n    X, y = self._validate_data(\n  File \"/usr/local/lib/python3.10/dist-packages/sklearn/base.py\", line 596, in _validate_data\n    X, y = check_X_y(X, y, **check_params)\n  File \"/usr/local/lib/python3.10/dist-packages/sklearn/utils/validation.py\", line 1074, in check_X_y\n    X = check_array(\n  File \"/usr/local/lib/python3.10/dist-packages/sklearn/utils/validation.py\", line 879, in check_array\n    raise ValueError(\nValueError: Expected 2D array, got 1D array instead:\narray=[0. 0. 0. ... 0. 0. 0.].\nReshape your data either using array.reshape(-1, 1) if your data has a single feature or array.reshape(1, -1) if it contains a single sample.\n",
     "output_type": "error",
     "traceback": [
      "\u001b[0;31m---------------------------------------------------------------------------\u001b[0m",
      "\u001b[0;31mValueError\u001b[0m                                Traceback (most recent call last)",
      "Cell \u001b[0;32mIn [19], line 7\u001b[0m\n\u001b[1;32m      5\u001b[0m svm_pred \u001b[39m=\u001b[39m SVM\u001b[39m.\u001b[39mpredict(pheno_test_X)\n\u001b[1;32m      6\u001b[0m \u001b[39mprint\u001b[39m(\u001b[39m\"\u001b[39m\u001b[39mPECC (accuracy):\u001b[39m\u001b[39m\"\u001b[39m, accuracy_score(pheno_test_y, svm_pred))\n\u001b[0;32m----> 7\u001b[0m cross_scores \u001b[39m=\u001b[39m cross_val_score(SVM, pheno_test_y, svm_pred, cv \u001b[39m=\u001b[39m \u001b[39m5\u001b[39m)\n\u001b[1;32m      8\u001b[0m \u001b[39mprint\u001b[39m(cross_scores)\n",
      "File \u001b[0;32m/usr/local/lib/python3.10/dist-packages/sklearn/model_selection/_validation.py:515\u001b[0m, in \u001b[0;36mcross_val_score\u001b[0;34m(estimator, X, y, groups, scoring, cv, n_jobs, verbose, fit_params, pre_dispatch, error_score)\u001b[0m\n\u001b[1;32m    512\u001b[0m \u001b[39m# To ensure multimetric format is not supported\u001b[39;00m\n\u001b[1;32m    513\u001b[0m scorer \u001b[39m=\u001b[39m check_scoring(estimator, scoring\u001b[39m=\u001b[39mscoring)\n\u001b[0;32m--> 515\u001b[0m cv_results \u001b[39m=\u001b[39m cross_validate(\n\u001b[1;32m    516\u001b[0m     estimator\u001b[39m=\u001b[39;49mestimator,\n\u001b[1;32m    517\u001b[0m     X\u001b[39m=\u001b[39;49mX,\n\u001b[1;32m    518\u001b[0m     y\u001b[39m=\u001b[39;49my,\n\u001b[1;32m    519\u001b[0m     groups\u001b[39m=\u001b[39;49mgroups,\n\u001b[1;32m    520\u001b[0m     scoring\u001b[39m=\u001b[39;49m{\u001b[39m\"\u001b[39;49m\u001b[39mscore\u001b[39;49m\u001b[39m\"\u001b[39;49m: scorer},\n\u001b[1;32m    521\u001b[0m     cv\u001b[39m=\u001b[39;49mcv,\n\u001b[1;32m    522\u001b[0m     n_jobs\u001b[39m=\u001b[39;49mn_jobs,\n\u001b[1;32m    523\u001b[0m     verbose\u001b[39m=\u001b[39;49mverbose,\n\u001b[1;32m    524\u001b[0m     fit_params\u001b[39m=\u001b[39;49mfit_params,\n\u001b[1;32m    525\u001b[0m     pre_dispatch\u001b[39m=\u001b[39;49mpre_dispatch,\n\u001b[1;32m    526\u001b[0m     error_score\u001b[39m=\u001b[39;49merror_score,\n\u001b[1;32m    527\u001b[0m )\n\u001b[1;32m    528\u001b[0m \u001b[39mreturn\u001b[39;00m cv_results[\u001b[39m\"\u001b[39m\u001b[39mtest_score\u001b[39m\u001b[39m\"\u001b[39m]\n",
      "File \u001b[0;32m/usr/local/lib/python3.10/dist-packages/sklearn/model_selection/_validation.py:285\u001b[0m, in \u001b[0;36mcross_validate\u001b[0;34m(estimator, X, y, groups, scoring, cv, n_jobs, verbose, fit_params, pre_dispatch, return_train_score, return_estimator, error_score)\u001b[0m\n\u001b[1;32m    265\u001b[0m parallel \u001b[39m=\u001b[39m Parallel(n_jobs\u001b[39m=\u001b[39mn_jobs, verbose\u001b[39m=\u001b[39mverbose, pre_dispatch\u001b[39m=\u001b[39mpre_dispatch)\n\u001b[1;32m    266\u001b[0m results \u001b[39m=\u001b[39m parallel(\n\u001b[1;32m    267\u001b[0m     delayed(_fit_and_score)(\n\u001b[1;32m    268\u001b[0m         clone(estimator),\n\u001b[0;32m   (...)\u001b[0m\n\u001b[1;32m    282\u001b[0m     \u001b[39mfor\u001b[39;00m train, test \u001b[39min\u001b[39;00m cv\u001b[39m.\u001b[39msplit(X, y, groups)\n\u001b[1;32m    283\u001b[0m )\n\u001b[0;32m--> 285\u001b[0m _warn_or_raise_about_fit_failures(results, error_score)\n\u001b[1;32m    287\u001b[0m \u001b[39m# For callabe scoring, the return type is only know after calling. If the\u001b[39;00m\n\u001b[1;32m    288\u001b[0m \u001b[39m# return type is a dictionary, the error scores can now be inserted with\u001b[39;00m\n\u001b[1;32m    289\u001b[0m \u001b[39m# the correct key.\u001b[39;00m\n\u001b[1;32m    290\u001b[0m \u001b[39mif\u001b[39;00m callable(scoring):\n",
      "File \u001b[0;32m/usr/local/lib/python3.10/dist-packages/sklearn/model_selection/_validation.py:367\u001b[0m, in \u001b[0;36m_warn_or_raise_about_fit_failures\u001b[0;34m(results, error_score)\u001b[0m\n\u001b[1;32m    360\u001b[0m \u001b[39mif\u001b[39;00m num_failed_fits \u001b[39m==\u001b[39m num_fits:\n\u001b[1;32m    361\u001b[0m     all_fits_failed_message \u001b[39m=\u001b[39m (\n\u001b[1;32m    362\u001b[0m         \u001b[39mf\u001b[39m\u001b[39m\"\u001b[39m\u001b[39m\\n\u001b[39;00m\u001b[39mAll the \u001b[39m\u001b[39m{\u001b[39;00mnum_fits\u001b[39m}\u001b[39;00m\u001b[39m fits failed.\u001b[39m\u001b[39m\\n\u001b[39;00m\u001b[39m\"\u001b[39m\n\u001b[1;32m    363\u001b[0m         \u001b[39m\"\u001b[39m\u001b[39mIt is very likely that your model is misconfigured.\u001b[39m\u001b[39m\\n\u001b[39;00m\u001b[39m\"\u001b[39m\n\u001b[1;32m    364\u001b[0m         \u001b[39m\"\u001b[39m\u001b[39mYou can try to debug the error by setting error_score=\u001b[39m\u001b[39m'\u001b[39m\u001b[39mraise\u001b[39m\u001b[39m'\u001b[39m\u001b[39m.\u001b[39m\u001b[39m\\n\u001b[39;00m\u001b[39m\\n\u001b[39;00m\u001b[39m\"\u001b[39m\n\u001b[1;32m    365\u001b[0m         \u001b[39mf\u001b[39m\u001b[39m\"\u001b[39m\u001b[39mBelow are more details about the failures:\u001b[39m\u001b[39m\\n\u001b[39;00m\u001b[39m{\u001b[39;00mfit_errors_summary\u001b[39m}\u001b[39;00m\u001b[39m\"\u001b[39m\n\u001b[1;32m    366\u001b[0m     )\n\u001b[0;32m--> 367\u001b[0m     \u001b[39mraise\u001b[39;00m \u001b[39mValueError\u001b[39;00m(all_fits_failed_message)\n\u001b[1;32m    369\u001b[0m \u001b[39melse\u001b[39;00m:\n\u001b[1;32m    370\u001b[0m     some_fits_failed_message \u001b[39m=\u001b[39m (\n\u001b[1;32m    371\u001b[0m         \u001b[39mf\u001b[39m\u001b[39m\"\u001b[39m\u001b[39m\\n\u001b[39;00m\u001b[39m{\u001b[39;00mnum_failed_fits\u001b[39m}\u001b[39;00m\u001b[39m fits failed out of a total of \u001b[39m\u001b[39m{\u001b[39;00mnum_fits\u001b[39m}\u001b[39;00m\u001b[39m.\u001b[39m\u001b[39m\\n\u001b[39;00m\u001b[39m\"\u001b[39m\n\u001b[1;32m    372\u001b[0m         \u001b[39m\"\u001b[39m\u001b[39mThe score on these train-test partitions for these parameters\u001b[39m\u001b[39m\"\u001b[39m\n\u001b[0;32m   (...)\u001b[0m\n\u001b[1;32m    376\u001b[0m         \u001b[39mf\u001b[39m\u001b[39m\"\u001b[39m\u001b[39mBelow are more details about the failures:\u001b[39m\u001b[39m\\n\u001b[39;00m\u001b[39m{\u001b[39;00mfit_errors_summary\u001b[39m}\u001b[39;00m\u001b[39m\"\u001b[39m\n\u001b[1;32m    377\u001b[0m     )\n",
      "\u001b[0;31mValueError\u001b[0m: \nAll the 5 fits failed.\nIt is very likely that your model is misconfigured.\nYou can try to debug the error by setting error_score='raise'.\n\nBelow are more details about the failures:\n--------------------------------------------------------------------------------\n1 fits failed with the following error:\nTraceback (most recent call last):\n  File \"/usr/local/lib/python3.10/dist-packages/sklearn/model_selection/_validation.py\", line 686, in _fit_and_score\n    estimator.fit(X_train, y_train, **fit_params)\n  File \"/usr/local/lib/python3.10/dist-packages/sklearn/svm/_base.py\", line 173, in fit\n    X, y = self._validate_data(\n  File \"/usr/local/lib/python3.10/dist-packages/sklearn/base.py\", line 596, in _validate_data\n    X, y = check_X_y(X, y, **check_params)\n  File \"/usr/local/lib/python3.10/dist-packages/sklearn/utils/validation.py\", line 1074, in check_X_y\n    X = check_array(\n  File \"/usr/local/lib/python3.10/dist-packages/sklearn/utils/validation.py\", line 879, in check_array\n    raise ValueError(\nValueError: Expected 2D array, got 1D array instead:\narray=[1. 1. 0. ... 0. 0. 0.].\nReshape your data either using array.reshape(-1, 1) if your data has a single feature or array.reshape(1, -1) if it contains a single sample.\n\n--------------------------------------------------------------------------------\n4 fits failed with the following error:\nTraceback (most recent call last):\n  File \"/usr/local/lib/python3.10/dist-packages/sklearn/model_selection/_validation.py\", line 686, in _fit_and_score\n    estimator.fit(X_train, y_train, **fit_params)\n  File \"/usr/local/lib/python3.10/dist-packages/sklearn/svm/_base.py\", line 173, in fit\n    X, y = self._validate_data(\n  File \"/usr/local/lib/python3.10/dist-packages/sklearn/base.py\", line 596, in _validate_data\n    X, y = check_X_y(X, y, **check_params)\n  File \"/usr/local/lib/python3.10/dist-packages/sklearn/utils/validation.py\", line 1074, in check_X_y\n    X = check_array(\n  File \"/usr/local/lib/python3.10/dist-packages/sklearn/utils/validation.py\", line 879, in check_array\n    raise ValueError(\nValueError: Expected 2D array, got 1D array instead:\narray=[0. 0. 0. ... 0. 0. 0.].\nReshape your data either using array.reshape(-1, 1) if your data has a single feature or array.reshape(1, -1) if it contains a single sample.\n"
     ]
    }
   ],
   "source": [
    "from sklearn import svm\n",
    "from sklearn.model_selection import cross_val_score\n",
    "SVM = svm.SVC()\n",
    "SVM = SVM.fit(pheno_train_X, pheno_train_y)\n",
    "svm_pred = SVM.predict(pheno_test_X)\n",
    "print(\"PECC (accuracy):\", accuracy_score(pheno_test_y, svm_pred))\n",
    "cross_scores = cross_val_score(SVM, pheno_test_y, svm_pred, cv = 5)\n",
    "print(cross_scores)\n"
   ]
  }
 ],
 "metadata": {
  "kernelspec": {
   "display_name": "Python 3.10.6 64-bit",
   "language": "python",
   "name": "python3"
  },
  "language_info": {
   "codemirror_mode": {
    "name": "ipython",
    "version": 3
   },
   "file_extension": ".py",
   "mimetype": "text/x-python",
   "name": "python",
   "nbconvert_exporter": "python",
   "pygments_lexer": "ipython3",
   "version": "3.10.6"
  },
  "orig_nbformat": 4,
  "vscode": {
   "interpreter": {
    "hash": "916dbcbb3f70747c44a77c7bcd40155683ae19c65e1c03b4aa3499c5328201f1"
   }
  }
 },
 "nbformat": 4,
 "nbformat_minor": 2
}
